/usr/share/Modules/init/sh: line 2: unalias: salloc: not found
/usr/share/Modules/init/sh: line 2: unalias: df: not found
Traceback (most recent call last):
  File "/work/van-speech-nlp/jindaznb/slamenv/lib/python3.10/site-packages/transformers/utils/import_utils.py", line 1567, in _get_module
  File "/work/van-speech-nlp/jindaznb/slamenv/lib/python3.10/importlib/__init__.py", line 126, in import_module
    return _bootstrap._gcd_import(name[level:], package, level)
  File "<frozen importlib._bootstrap>", line 1050, in _gcd_import
  File "<frozen importlib._bootstrap>", line 1027, in _find_and_load
  File "<frozen importlib._bootstrap>", line 992, in _find_and_load_unlocked
  File "<frozen importlib._bootstrap>", line 241, in _call_with_frames_removed
  File "<frozen importlib._bootstrap>", line 1050, in _gcd_import
  File "<frozen importlib._bootstrap>", line 1027, in _find_and_load
  File "<frozen importlib._bootstrap>", line 1006, in _find_and_load_unlocked
  File "<frozen importlib._bootstrap>", line 688, in _load_unlocked
  File "<frozen importlib._bootstrap_external>", line 883, in exec_module
  File "<frozen importlib._bootstrap>", line 241, in _call_with_frames_removed
  File "/work/van-speech-nlp/jindaznb/slamenv/lib/python3.10/site-packages/transformers/data/__init__.py", line 27, in <module>
ModuleNotFoundError: No module named 'transformers.data.processors'

The above exception was the direct cause of the following exception:

Traceback (most recent call last):
  File "/work/van-speech-nlp/jindaznb/jslpnb/mllm_experiments/slam-llm/examples/asr_librispeech/inference_asr_batch.py", line 1, in <module>
    from slam_llm.pipeline.inference_batch import main as inference
  File "/work/van-speech-nlp/jindaznb/jslpnb/mllm_experiments/slam-llm/src/slam_llm/pipeline/inference_batch.py", line 6, in <module>
    from slam_llm.models.slam_model import slam_model
  File "/work/van-speech-nlp/jindaznb/jslpnb/mllm_experiments/slam-llm/src/slam_llm/models/slam_model.py", line 12, in <module>
    from slam_llm.utils.config_utils import generate_peft_config
  File "/work/van-speech-nlp/jindaznb/jslpnb/mllm_experiments/slam-llm/src/slam_llm/utils/config_utils.py", line 14, in <module>
    from transformers import default_data_collator
  File "<frozen importlib._bootstrap>", line 1075, in _handle_fromlist
  File "/work/van-speech-nlp/jindaznb/slamenv/lib/python3.10/site-packages/transformers/utils/import_utils.py", line 1557, in __getattr__
  File "/work/van-speech-nlp/jindaznb/slamenv/lib/python3.10/site-packages/transformers/utils/import_utils.py", line 1569, in _get_module
RuntimeError: Failed to import transformers.data.data_collator because of the following error (look up to see its traceback):
No module named 'transformers.data.processors'
